Workbook
Name nrGeneratedAt: 'Dashboard'!$A$2
Name nrReviewOpenCount: 'TemplateInfo'!$B$2
Name nrReviewDeferredCount: 'TemplateInfo'!$B$3
Name nrReviewResolvedCount: 'TemplateInfo'!$B$4
Name nrCampaignActionCount: 'TemplateInfo'!$B$5
Name nrCampaignRepoCount: 'TemplateInfo'!$B$6
Name nrGovernanceReadyCount: 'TemplateInfo'!$B$7
Name nrGovernanceDriftCount: 'TemplateInfo'!$B$8
Name nrPortfolioGrade: 'TemplateInfo'!$B$9
Name nrAverageScore: 'TemplateInfo'!$B$10
Name nrLatestReviewState: 'TemplateInfo'!$B$11
Name nrSelectedProfileLabel: 'TemplateInfo'!$B$12
Name nrSelectedCollectionLabel: 'TemplateInfo'!$B$13

Sheet Index
A1: GitHub Portfolio Audit: sample-user | J1: Quick Links
A2: Last updated: 2026-04-12 | 3 repos | Grade: B | J2: Dashboard
A3: Use this workbook in order: Dashboard for the brief, Run Changes for movement, Review Queue for action, Repo Detail for one-repo context, and Executive Summary for a shareable recap. | J3: Review Queue
A4: Start Here | J4: Repo Detail
A5: Workbook Mode | B5: standard | C5: Profile | D5: default | J5: Run Changes
A6: Collection | B6: all | C6: Source Run | D6: sample-user:2026-04-12T12:00:00+00:00 | J6: Executive Summary
A7: Report Reference | C7: Operator Headline | D7: RepoC still needs security follow-through before the queue will calm down.
A8: Next Run | B8: incremental | C8: Watch Strategy | D8: adaptive
A9: The current baseline is still compatible, so incremental watch remains safe for the next run.
A10: What changed: RepoC drift needs review and RepoB reopened a release checklist item.
A11: Why it matters: Live drift is still present, so security work should stay ahead of lower-pressure cleanup.
A12: What to do next: Review RepoC first, then close RepoB's reopened checklist item.
A13: Follow-through: One urgent item is still repeating in the recent window.
A14: Escalation: No stronger follow-through escalation is currently surfaced.
A15: Start with Dashboard for the portfolio brief, move to Review Queue for action, then drill into Portfolio Explorer and Executive Summary for detail.
A16: Operating rules: standard mode is the default path, visible sheets stay filter-based, and hidden Data_* sheets remain the workbook contract. Advanced sheets are hidden by default; use Excel Unhide when you need deeper diagnostics.
E17: Portfolio Analysis
A18: Daily Triage | E18: Sheet | F18: Use This When | G18: Go
A19: Sheet | B19: Use This When | C19: Go | E19: Portfolio Explorer | F19: Rank repos, compare score quality, and drill from summary into raw facts. | G19: Open
A20: Dashboard | B20: Start here for the big-picture health view and top attention items. | C20: Open | E20: Repo Detail | F20: Select one repo and get a single-page briefing on score, risks, trend, and next action. | G20: Open
A21: Review Queue | B21: Use this for blocked, urgent, ready, and safe-to-defer review work. | C21: Open | E21: By Lens | F21: Compare the portfolio by ship readiness, momentum, security, and fit. | G21: Open
A22: Run Changes | B22: See what changed since the last run before you decide where to spend attention. | C22: Open | E22: By Collection | F22: Understand collection-level leaders and concentration. | G22: Open
A23: Campaigns | B23: Check managed campaign state, reopen/closure context, and drift. | C23: Open | E23: Trend Summary | F23: See portfolio-wide movement and repo trendlines over time. | G23: Open
A24: Governance Controls | B24: Review governed controls, approval posture, and rollback visibility. | C24: Open | E24: All Repos | F24: Scan the full inventory with grades, tiers, and supporting evidence. | G24: Open
A25: Writeback Audit | B25: See what writeback changed and what is reversible. | C25: Open
A27: Executive Readout | E27: Deep Diagnostics
A28: Sheet | B28: Use This When | C28: Go | E28: Sheet | F28: Use This When | G28: Go
A29: Executive Summary | B29: Readable leadership summary with what changed and what matters this week. | C29: Open | E29: Security | F29: Raw security posture, secrets, and dangerous-file findings. | G29: Open
A30: Print Pack | B30: Print-friendly handoff with risks, opportunities, and operator counts in plain language. | C30: Open | E30: Security Controls | F30: Control coverage and rollout detail by repo. | G30: Open
E31: Supply Chain | F31: Dependency health, scorecard signals, and provider coverage. | G31: Open
E32: Scoring Heatmap | F32: Dimension-by-dimension matrix for detailed score inspection. | G32: Open
E33: Hotspots | F33: Highest-severity risks and opportunities across the portfolio. | G33: Open
E34: Review History | F34: Recurring review history and decision-state ledger. | G34: Open
E35: Governance Audit | F35: Approval, drift, and rollback evidence summary. | G35: Open
E36: Score Explainer | F36: How scores, grades, and tiers are computed. | G36: Open
E37: Action Items | F37: Prioritized improvement ideas with effort context. | G37: Open

Sheet Dashboard
A1: GitHub Portfolio Dashboard: sample-user | AO1: Quick Links
A2: Generated: 2026-04-12 | 3 repos audited | AO2: Dashboard
A3: Since last audit (2026-04-05): | avg score +0.020 | 2 tier changes | Priority: RepoC needs 0.110 to promote | AO3: Review Queue
A4: Portfolio Health Snapshot | O4: Operator Attention Snapshot | AO4: Repo Detail
A5: Portfolio Grade | C5: Avg Score | E5: Shipped | G5: Functional | I5: WIP | K5: Needs Work | O5: Operator Snapshot | AO5: Run Changes
A6: B | C6: 0.65 | E6: 1 | G6: 1 | I6: 1 | K6: 0 | O6: Setup Health | P6: Ok | AO6: Executive Summary
O7: Operator Headline | P7: RepoC still needs security follow-through before the queue will calm down.
A8: Portfolio DNA | M8: Run Summary | N8: Average score moved +0.020; 0 meaningful improvements, 0 regressions, 1 promotions, and 1 demotions were recorded. | O8: Queue Counts | P8: 1 blocked, 1 urgent, 1 ready, 1 deferred
A9: Use the left side for portfolio shape and the right side for operator pressure. If you only have a minute, read the narrative, scan the queue snapshot, and then open Review Queue. | M9: Queue Pressure | N9: 1 blocked, 1 urgent, 1 ready, and 1 deferred item(s) are currently in the queue. | O9: Governance | P9: Governed security drift needs review.
M10: Trust Summary | N10: verify-first — The recommendation is sound, but recent reopen noise means it should still be reviewed before acting. | O10: Campaign State | P10: Security Review | X10: Shipped | Y10: 1 | AA10: A | AB10: 1 | AD10: Python | AE10: 2 | AG10: RepoA | AH10: 0.88 | AI10: 0.61 | AJ10: 0.55 | AK10: 0 | AL10: 0 | AM10: 0.45
M11: Top Recommendation | N11: Review RepoC first, then close RepoB's reopened checklist item. Start with RepoC if you need a concrete place to begin. | O11: Run Changes | P11: Average score moved +0.020; 0 meaningful improvements, 0 regressions, 1 promotions, and 1 demotions were recorded. | X11: Functional | Y11: 1 | AA11: B | AB11: 0 | AD11: TypeScript | AE11: 1 | AG11: RepoB | AH11: 0.62 | AI11: 0.37 | AJ11: 0.55 | AK11: 1 | AL11: 1 | AM11: 0.45
M12: Use This Page | N12: Read the left side for portfolio shape, the right side for operator pressure, then jump into Review Queue or Repo Detail. | O12: Queue Pressure | P12: 1 blocked, 1 urgent, 1 ready, and 1 deferred item(s) are currently in the queue. | X12: Wip | Y12: 1 | AA12: C | AB12: 1 | AG12: RepoC | AH12: 0.44 | AI12: 0.16
O13: What Changed | P13: RepoC drift needs review and RepoB reopened a release checklist item. | X13: Skeleton | Y13: 0 | AA13: D | AB13: 1
O14: Why It Matters | P14: Live drift is still present, so security work should stay ahead of lower-pressure cleanup. | X14: Abandoned | Y14: 0 | AA14: F | AB14: 0
O15: Follow-Through | P15: One urgent item is still repeating in the recent window.
O16: Next Checkpoint | P16: Use the next run or linked artifact to confirm whether the recommendation moved.
O17: Escalation | P17: No stronger follow-through escalation is currently surfaced.
O18: Recovery / Retirement | P18: No follow-through recovery or escalation-retirement signal is currently surfaced.
O19: Recovery Persistence | P19: No follow-through recovery persistence signal is currently surfaced.
O20: Relapse Churn | P20: No relapse churn is currently surfaced.
O21: Recovery Freshness | P21: No follow-through recovery freshness signal is currently surfaced.
O22: Recovery Memory Reset | P22: No follow-through recovery memory reset signal is currently surfaced.
O23: Recovery Rebuild Strength | P23: No follow-through recovery rebuild-strength signal is currently surfaced.
O24: Recovery Reacquisition | P24: No follow-through recovery reacquisition signal is currently surfaced.
O25: Reacquisition Durability | P25: No follow-through reacquisition durability signal is currently surfaced.
O26: Reacquisition Confidence | P26: No follow-through reacquisition confidence-consolidation signal is currently surfaced.
... O30: Portfolio Catalog | P30: No portfolio catalog contract is recorded yet.
A31: Highlights | O31: Operating Paths | P31: No normalized operating-path contract is recorded yet.
O32: Intent Alignment | P32: Intent alignment cannot be judged until a portfolio catalog contract exists.
O33: Scorecards | P33: No maturity scorecard is recorded yet.
O34: Next Action | P34: Review RepoC first, then close RepoB's reopened checklist item.
O35: Top Recommendation | P35: Review RepoC first, then close RepoB's reopened checklist item. Start with RepoC if you need a concrete place to begin.
O36: Trend | P36: Stable — Queue pressure is stable but still sticky.
O37: Primary Target | P37: No active target
O38: Resolution Counts | P38: New 0 | Resolved 0 | Persisting 0
O39: Recovery Hotspot | P39: No active recovery or retirement hotspot
O40: Retiring Watch Hotspot | P40: No active recovery or retirement hotspot
O41: Churn Hotspot | P41: No relapse-churn hotspot
O42: Freshness Hotspot | P42: No stale recovery-memory hotspot
O43: Freshness Detail | P43: No follow-through recovery freshness signal is currently surfaced.
...

Sheet Review Queue
A1: Review Queue | AQ1: Quick Links
A2: Start with the summary strip, then use the full queue below when you need row-level facts and decision context. | AQ2: Dashboard
A3: Work this page in lane order: clear Blocked first, handle Needs Attention Now next, and only then move into Ready for Manual Action or Safe to Defer. | AQ3: Review Queue
A4: Summary | E4: Top 10 To Act On | AQ4: Repo Detail
A5: Headline | B5: RepoC still needs security follow-through before the queue will calm down. | E5: Repo | F5: Primary Lane | G5: Counts | H5: Why Now | I5: Next Step | AQ5: Run Changes
A6: Queue Counts | B6: 1 blocked, 1 urgent, 1 ready, 1 deferred | E6: RepoC | F6: Blocked | G6: 1 blocked, 0 urgent, 0 ready, 0 deferred | H6: Security drift needs review | I6: Open the governed control preview and decide whether to apply CodeQL. | AQ6: Executive Summary
A7: Queue Pressure | B7: 1 blocked, 1 urgent, 1 ready, and 1 deferred item(s) are currently in the queue. | E7: RepoB | F7: Needs Attention Now | G7: 0 blocked, 1 urgent, 0 ready, 0 deferred | H7: Release checklist reopened | I7: Re-run the release checklist and close the missing item.
A8: Total Queue Items | B8: 4 | E8: RepoA | F8: Ready for Manual Action | G8: 0 blocked, 0 urgent, 1 ready, 1 deferred | H8: Archive old brainstorm notes | I8: Leave this alone unless priorities change.
A9: Immediate Focus | B9: Open the governed control preview and decide whether to apply CodeQL.
A10: Top Recommendation | B10: Review RepoC first, then close RepoB's reopened checklist item.
A11: Top Issue Family | B11: Security Change (1)
A12: Trend | B12: Stable — Queue pressure is stable but still sticky.
A13: Primary Target | B13: No active target
A14: Resolution Counts | B14: New 0 | Resolved 0 | Persisting 0
A15: Why Top Target | B15: RepoC remains the top target because live drift is still open.
A16: Closure Guidance | B16: Clear RepoC's security drift before moving to lower-pressure work.
A17: Aging Pressure | B17: Chronic 0 | Newly stale 0 | Longest No persisting item
A18: What We Tried | B18: No recent intervention recorded
A19: Last Outcome | B19: No Change
A20: Resolution Evidence | B20: No resolution evidence is recorded yet.
... A58: Source Run | B58: sample-user:2026-04-12T12:00:00+00:00
A60: Top Issue Families | E60: Top Recommended Actions
A61: Issue Family | B61: Count | E61: Action | F61: Count
A62: Security Change | B62: 1 | E62: Open the governed control preview and decide whether to apply CodeQL. | F62: 1
A63: Reopened Review | B63: 1 | E63: Re-run the release checklist and close the missing item. | F63: 1
E64: Tidy the release notes and publish the next small maintenance release. | F64: 1
E65: Leave this alone unless priorities change. | F65: 1
A67: Read this table top-down: urgent items first, ready items second, and safe-to-defer rows last.
A68: Repo | B68: Title | C68: Lane | D68: Kind | E68: Priority | F68: Why This Is Here | G68: What To Do Next | H68: Catalog | I68: Operating Path | J68: Intent Alignment | K68: Maturity | L68: Scorecard Gap | M68: Last Movement | N68: Follow-Through | O68: Next Checkpoint | P68: Checkpoint Timing | Q68: Escalation | R68: Escalation Summary | S68: Recovery / Retirement | T68: Recovery Summary | U68: Recovery Persistence | V68: Persistence Summary | W68: Relapse Churn | X68: Churn Summary | Y68: Recovery Freshness | Z68: Freshness Summary | AA68: Recovery Memory Reset | AB68: Reset Summary | AC68: Recovery Rebuild Strength | AD68: Rebuild Summary | AE68: Recovery Reacquisition | AF68: Reacquisition Summary | AG68: Reacquisition Durability | AH68: Durability Summary | AI68: Reacquisition Confidence | AJ68: Confidence Summary | AK68: Operator Focus | AL68: Focus Summary | AM68: Focus Line | AN68: Open Artifact | AO68: Safe To Defer
A69: RepoC | B69: Security drift needs review | C69: blocked | D69: campaign | E69: 1 | F69: Governed security drift is still unresolved. | G69: Open the governed control preview and decide whether to apply CodeQL. | H69: No portfolio catalog contract is recorded yet. | I69: Operating Path: Unspecified (legacy confidence) — No operating-path rationale is recorded yet. | J69: missing-contract — Intent alignment cannot be judged until a portfolio catalog contract exists. | K69: — | L69: No maturity gap summary is recorded yet. | M69: Current run | N69: No follow-through evidence is recorded yet. | O69: Use the next run or linked artifact to confirm whether the recommendation moved. | P69: Unknown | Q69: Unknown | R69: No stronger follow-through escalation is currently surfaced. | S69: None | T69: No follow-through recovery or escalation-retirement signal is currently surfaced. | U69: None | V69: No follow-through recovery persistence signal is currently surfaced. | W69: None | X69: No relapse churn is currently surfaced. | Y69: None | Z69: No follow-through recovery freshness signal is currently surfaced. | AA69: None | AB69: No follow-through recovery memory reset signal is currently surfaced. | AC69: None | AD69: No follow-through recovery rebuild-strength signal is currently surfaced. | AE69: None | AF69: No follow-through recovery reacquisition signal is currently surfaced. | AG69: None | AH69: No follow-through reacquisition durability signal is currently surfaced. | AI69: None | AJ69: No follow-through reacquisition confidence-consolidation signal is currently surfaced. | AK69: Act Now | AL69: Governed security drift is still unresolved. | AM69: Act Now: Governed security drift is still unresolved. | AN69: Open linked artifact | AO69: no
A70: RepoB | B70: Release checklist reopened | C70: urgent | D70: review | E70: 2 | F70: A previously quiet repo reopened a visible checklist item. | G70: Re-run the release checklist and close the missing item. | H70: No portfolio catalog contract is recorded yet. | I70: Operating Path: Unspecified (legacy confidence) — No operating-path rationale is recorded yet. | J70: missing-contract — Intent alignment cannot be judged until a portfolio catalog contract exists. | K70: — | L70: No maturity gap summary is recorded yet. | M70: Current run | N70: No follow-through evidence is recorded yet. | O70: Use the next run or linked artifact to confirm whether the recommendation moved. | P70: Unknown | Q70: Unknown | R70: No stronger follow-through escalation is currently surfaced. | S70: None | T70: No follow-through recovery or escalation-retirement signal is currently surfaced. | U70: None | V70: No follow-through recovery persistence signal is currently surfaced. | W70: None | X70: No relapse churn is currently surfaced. | Y70: None | Z70: No follow-through recovery freshness signal is currently surfaced. | AA70: None | AB70: No follow-through recovery memory reset signal is currently surfaced. | AC70: None | AD70: No follow-through recovery rebuild-strength signal is currently surfaced. | AE70: None | AF70: No follow-through recovery reacquisition signal is currently surfaced. | AG70: None | AH70: No follow-through reacquisition durability signal is currently surfaced. | AI70: None | AJ70: No follow-through reacquisition confidence-consolidation signal is currently surfaced. | AK70: Act Now | AL70: A previously quiet repo reopened a visible checklist item. | AM70: Act Now: A previously quiet repo reopened a visible checklist item. | AN70: No linked artifact available yet. | AO70: no
A71: RepoA | B71: Protect shipped momentum | C71: ready | D71: maintenance | E71: 3 | F71: RepoA is healthy enough that a small polish task would keep it strong. | G71: Tidy the release notes and publish the next small maintenance release. | H71: No portfolio catalog contract is recorded yet. | I71: Operating Path: Unspecified (legacy confidence) — No operating-path rationale is recorded yet. | J71: missing-contract — Intent alignment cannot be judged until a portfolio catalog contract exists. | K71: — | L71: No maturity gap summary is recorded yet. | M71: Current run | N71: No follow-through evidence is recorded yet. | O71: Use the next run or linked artifact to confirm whether the recommendation moved. | P71: Unknown | Q71: Unknown | R71: No stronger follow-through escalation is currently surfaced. | S71: None | T71: No follow-through recovery or escalation-retirement signal is currently surfaced. | U71: None | V71: No follow-through recovery persistence signal is currently surfaced. | W71: None | X71: No relapse churn is currently surfaced. | Y71: None | Z71: No follow-through recovery freshness signal is currently surfaced. | AA71: None | AB71: No follow-through recovery memory reset signal is currently surfaced. | AC71: None | AD71: No follow-through recovery rebuild-strength signal is currently surfaced. | AE71: None | AF71: No follow-through recovery reacquisition signal is currently surfaced. | AG71: None | AH71: No follow-through reacquisition durability signal is currently surfaced. | AI71: None | AJ71: No follow-through reacquisition confidence-consolidation signal is currently surfaced. | AK71: Watch Closely | AL71: No follow-through evidence is recorded yet. | AM71: Watch Closely: No follow-through evidence is recorded yet. | AN71: No linked artifact available yet. | AO71: no
A72: RepoA | B72: Archive old brainstorm notes | C72: deferred | D72: cleanup | E72: 4 | F72: This is cleanup-only work with no current pressure. | G72: Leave this alone unless priorities change. | H72: No portfolio catalog contract is recorded yet. | I72: Operating Path: Unspecified (legacy confidence) — No operating-path rationale is recorded yet. | J72: missing-contract — Intent alignment cannot be judged until a portfolio catalog contract exists. | K72: — | L72: No maturity gap summary is recorded yet. | M72: Current run | N72: No follow-through evidence is recorded yet. | O72: Use the next run or linked artifact to confirm whether the recommendation moved. | P72: Unknown | Q72: Unknown | R72: No stronger follow-through escalation is currently surfaced. | S72: None | T72: No follow-through recovery or escalation-retirement signal is currently surfaced. | U72: None | V72: No follow-through recovery persistence signal is currently surfaced. | W72: None | X72: No relapse churn is currently surfaced. | Y72: None | Z72: No follow-through recovery freshness signal is currently surfaced. | AA72: None | AB72: No follow-through recovery memory reset signal is currently surfaced. | AC72: None | AD72: No follow-through recovery rebuild-strength signal is currently surfaced. | AE72: None | AF72: No follow-through recovery reacquisition signal is currently surfaced. | AG72: None | AH72: No follow-through reacquisition durability signal is currently surfaced. | AI72: None | AJ72: No follow-through reacquisition confidence-consolidation signal is currently surfaced. | AK72: Watch Closely | AL72: No follow-through evidence is recorded yet. | AM72: Watch Closely: No follow-through evidence is recorded yet. | AN72: No linked artifact available yet. | AO72: yes

Sheet Portfolio Explorer
A1: Portfolio Explorer | R1: Quick Links
A2: Use this sheet to rank the portfolio, sort by profile-aware score, and drill from summary into repo-level facts. | R2: Dashboard
A3: How to use this sheet: sort by Profile Score first, then use the catalog columns to separate intentional experiments from maintained assets before drilling in. | R3: Review Queue
R4: Repo Detail
A5: Repo | B5: Profile Score | C5: Overall | D5: Interest | E5: Tier | F5: Collections | G5: Lifecycle | H5: Criticality | I5: Disposition | J5: Operating Path | K5: Maturity | L5: Scorecard Gap | M5: Security | N5: Hotspots | O5: Top Hotspot | P5: Primary Action | R5: Run Changes
A6: RepoA | B6: 0.88 | C6: 0.88 | D6: 0.61 | E6: shipped | F6: showcase | G6: — | H6: — | I6: — | J6: — | K6: — | L6: No maturity gap summary is recorded yet. | M6: healthy | N6: 1 | O6: Keep release notes fresh | P6: Publish the next maintenance release | R6: Executive Summary
A7: RepoB | B7: 0.62 | C7: 0.62 | D7: 0.37 | E7: functional | G7: — | H7: — | I7: — | J7: — | K7: — | L7: No maturity gap summary is recorded yet. | M7: watch | N7: 1 | O7: Finish release checklist | P7: Close the reopened release item
A8: RepoC | B8: 0.44 | C8: 0.44 | D8: 0.16 | E8: wip | G8: — | H8: — | I8: — | J8: — | K8: — | L8: No maturity gap summary is recorded yet. | M8: critical | N8: 1 | O8: Security posture needs attention | P8: Preview governance controls

Sheet Implementation Hotspots
A1: Implementation Hotspots
A2: No meaningful implementation hotspots are currently surfaced.
A4: Repo | B4: Scope | C4: Path | D4: Module | E4: Category | F4: Pressure | G4: Suggestion | H4: Why It Matters | I4: Suggested First Move

Sheet Operator Outcomes
A1: Operator Outcomes
A2: Not enough operator history is recorded yet to judge outcomes.
A3: Not enough judged recommendation history is recorded yet to judge operator effectiveness.
A4: High-pressure queue trend is not ready yet.
A5: No recent Action Sync apply needs post-apply monitoring yet, so the local weekly story can stay local.
A6: Stay local for now; no recent Action Sync apply needs post-apply follow-up yet.
A7: Campaign tuning is neutral because there is not enough outcome history yet to bias tied recommendations.
A8: No current campaign needs a tuning tie-break yet.
A9: Automation guidance stays quiet until a campaign has a clearly safe preview, follow-up, or manual-only posture.
A10: Stay local for now; no current campaign has a stronger safe automation posture than manual review.
A11: No current approval needs review yet, so the approval workflow can stay local for now.
A12: Stay local for now; no current approval needs review.
A14: Metric | B14: Status | C14: Value | D14: Numerator | E14: Denominator | F14: Summary
A15: Review To Action Closure Rate | B15: insufficient-evidence
A16: Median Runs To Quiet After Escalation | B16: insufficient-evidence
A17: Repeated Regression Rate | B17: insufficient-evidence
A18: Recommendation Validation Rate | B18: insufficient-evidence
A19: Noisy Guidance Rate | B19: insufficient-evidence
A22: Post-Apply Monitoring
A23: Campaign | B23: State | C23: Pressure Effect | D23: Drift | E23: Reopen | F23: Summary
A30: Recent Examples
A31: Closed Actions | B31: No recent examples are recorded yet.
A32: Reopened Recommendations | B32: No recent examples are recorded yet.
A33: Regression Examples | B33: No recent examples are recorded yet.
A36: Run | B36: Generated | C36: Blocked | D36: Urgent | E36: High Pressure

Sheet Approval Ledger
A1: Approval Ledger
A2: No current approval needs review yet, so the approval workflow can stay local for now.
A3: Stay local for now; no current approval needs review.
A5: Label | B5: State | C5: Follow-Up | D5: Subject | E5: Reviewer | F5: Approved At | G5: Next Follow-Up Due | H5: Summary
A6: Needs Re-Approval
A7: None
A8: Overdue Follow-Up
A9: None
A10: Ready For Review
A11: None
A12: Due Soon Follow-Up
A13: None
A14: Approved But Manual
A15: None
A16: Blocked
A17: None

Sheet Historical Intelligence
A1: Historical Portfolio Intelligence
A2: Historical portfolio intelligence is still thin, so the weekly story should stay grounded in the current run and recent operator queue.
A3: Stay local for now; no repo has enough cross-run intervention evidence to demand a historical follow-up read yet.
A5: Repo | B5: Status | C5: Pressure Trend | D5: Hotspot Persistence | E5: Scorecard Trend | F5: Summary
A6: Relapsing
A7: No repos currently show a relapsing story.
A9: Persistent Pressure
A10: No repos currently show a persistent pressure story.
A12: Improving After Intervention
A13: No repos currently show a improving after intervention story.
A15: Holding Steady
A16: No repos currently show a holding steady story.

Sheet Repo Detail
A1: Repo Detail | L1: Quick Links
A2: Pick one repo, then use this page as the fastest single-repo briefing: score, tier, trend, risks, and next move. | L2: Dashboard
A3: Choose one repo, skim the briefing blocks top to bottom, then jump to Run Changes or Review Queue if you need more context. | L3: Review Queue
A4: Select Repo | B4: RepoA | D4: GitHub | E4: =IFERROR(IF(VLOOKUP($B$4,Data_RepoDetail!$A:$BZ,2,FALSE)="","Repo URL unavailable",HYPERLINK(VLOOKUP($B$4,Data_RepoDetail!$A:$BZ,2,FALSE),"Open Repo")),"Repo URL unavailable") | L4: Repo Detail
L5: Run Changes
A6: Repo | B6: =IFERROR(IF(VLOOKUP($B$4,Data_RepoDetail!$A:$BZ,1,FALSE)="","No repo selected.",VLOOKUP($B$4,Data_RepoDetail!$A:$BZ,1,FALSE)),"No repo selected.") | D6: Language | E6: =IFERROR(IF(VLOOKUP($B$4,Data_RepoDetail!$A:$BZ,3,FALSE)="","Unknown",VLOOKUP($B$4,Data_RepoDetail!$A:$BZ,3,FALSE)),"Unknown") | G6: Badges | H6: =IFERROR(IF(VLOOKUP($B$4,Data_RepoDetail!$A:$BZ,9,FALSE)="","None",VLOOKUP($B$4,Data_RepoDetail!$A:$BZ,9,FALSE)),"None") | L6: Executive Summary
A7: Overall Score | B7: =IFERROR(VLOOKUP($B$4,Data_RepoDetail!$A:$BZ,5,FALSE),"") | D7: Interest Score | E7: =IFERROR(VLOOKUP($B$4,Data_RepoDetail!$A:$BZ,6,FALSE),"") | G7: Flags | H7: =IFERROR(IF(VLOOKUP($B$4,Data_RepoDetail!$A:$BZ,10,FALSE)="","None",VLOOKUP($B$4,Data_RepoDetail!$A:$BZ,10,FALSE)),"None")
A8: Grade | B8: =IFERROR(IF(VLOOKUP($B$4,Data_RepoDetail!$A:$BZ,7,FALSE)="","—",VLOOKUP($B$4,Data_RepoDetail!$A:$BZ,7,FALSE)),"—") | D8: Tier | E8: =IFERROR(IF(VLOOKUP($B$4,Data_RepoDetail!$A:$BZ,8,FALSE)="","—",VLOOKUP($B$4,Data_RepoDetail!$A:$BZ,8,FALSE)),"—") | G8: Collections | H8: =IFERROR(IF(VLOOKUP($B$4,Data_RepoDetail!$A:$BZ,11,FALSE)="","—",VLOOKUP($B$4,Data_RepoDetail!$A:$BZ,11,FALSE)),"—")
A9: Security | B9: =IFERROR(IF(VLOOKUP($B$4,Data_RepoDetail!$A:$BZ,12,FALSE)="","unknown",VLOOKUP($B$4,Data_RepoDetail!$A:$BZ,12,FALSE)),"unknown") | D9: Security Score | E9: =IFERROR(VLOOKUP($B$4,Data_RepoDetail!$A:$BZ,13,FALSE),"") | G9: Trend | H9: =IFERROR(IF(VLOOKUP($B$4,Data_RepoDetail!$A:$BZ,18,FALSE)="","No trend history yet.",VLOOKUP($B$4,Data_RepoDetail!$A:$BZ,18,FALSE)),"No trend history yet.")
A11: Description | B11: =IFERROR(IF(VLOOKUP($B$4,Data_RepoDetail!$A:$BZ,4,FALSE)="","No description recorded yet.",VLOOKUP($B$4,Data_RepoDetail!$A:$BZ,4,FALSE)),"No description recorded yet.")
A13: Current State | E13: Why This Repo Looks This Way
A14: Ship Readiness | B14: =IFERROR(IF(VLOOKUP($B$4,Data_RepoDetail!$A:$BZ,14,FALSE)="","No summary recorded yet.",VLOOKUP($B$4,Data_RepoDetail!$A:$BZ,14,FALSE)),"No summary recorded yet.") | E14: Strongest Drivers | F14: =IFERROR(IF(VLOOKUP($B$4,Data_RepoDetail!$A:$BZ,19,FALSE)="","No briefing detail recorded yet.",VLOOKUP($B$4,Data_RepoDetail!$A:$BZ,19,FALSE)),"No briefing detail recorded yet.")
A15: Momentum | B15: =IFERROR(IF(VLOOKUP($B$4,Data_RepoDetail!$A:$BZ,15,FALSE)="","No summary recorded yet.",VLOOKUP($B$4,Data_RepoDetail!$A:$BZ,15,FALSE)),"No summary recorded yet.") | E15: Biggest Drags | F15: =IFERROR(IF(VLOOKUP($B$4,Data_RepoDetail!$A:$BZ,20,FALSE)="","No briefing detail recorded yet.",VLOOKUP($B$4,Data_RepoDetail!$A:$BZ,20,FALSE)),"No briefing detail recorded yet.")
A16: Security | B16: =IFERROR(IF(VLOOKUP($B$4,Data_RepoDetail!$A:$BZ,16,FALSE)="","No summary recorded yet.",VLOOKUP($B$4,Data_RepoDetail!$A:$BZ,16,FALSE)),"No summary recorded yet.") | E16: Last Movement | F16: =IFERROR(IF(VLOOKUP($B$4,Data_RepoDetail!$A:$BZ,30,FALSE)="","No briefing detail recorded yet.",VLOOKUP($B$4,Data_RepoDetail!$A:$BZ,30,FALSE)),"No briefing detail recorded yet.")
A17: Portfolio Fit | B17: =IFERROR(IF(VLOOKUP($B$4,Data_RepoDetail!$A:$BZ,17,FALSE)="","No summary recorded yet.",VLOOKUP($B$4,Data_RepoDetail!$A:$BZ,17,FALSE)),"No summary recorded yet.") | E17: Next Tier Gap | F17: =IFERROR(IF(VLOOKUP($B$4,Data_RepoDetail!$A:$BZ,21,FALSE)="","No briefing detail recorded yet.",VLOOKUP($B$4,Data_RepoDetail!$A:$BZ,21,FALSE)),"No briefing detail recorded yet.")
E18: Next Best Action | F18: =IFERROR(IF(VLOOKUP($B$4,Data_RepoDetail!$A:$BZ,22,FALSE)="","No briefing detail recorded yet.",VLOOKUP($B$4,Data_RepoDetail!$A:$BZ,22,FALSE)),"No briefing detail recorded yet.")
E19: Why This Action | F19: =IFERROR(IF(VLOOKUP($B$4,Data_RepoDetail!$A:$BZ,23,FALSE)="","No briefing detail recorded yet.",VLOOKUP($B$4,Data_RepoDetail!$A:$BZ,23,FALSE)),"No briefing detail recorded yet.")
A20: Dimension Breakdown | F20: What Changed
A21: Rank | B21: Dimension | C21: Score | D21: Summary | F21: Hotspot 1 | G21: =IFERROR(IF(VLOOKUP($B$4,Data_RepoDetail!$A:$BZ,24,FALSE)="","No hotspot recorded yet.",VLOOKUP($B$4,Data_RepoDetail!$A:$BZ,24,FALSE)),"No hotspot recorded yet.")
A22: 1 | B22: =IFERROR(VLOOKUP($B$4&"::1",Data_RepoDimensionRollups!$A:$F,4,FALSE),"") | C22: =IFERROR(VLOOKUP($B$4&"::1",Data_RepoDimensionRollups!$A:$F,5,FALSE),"") | D22: =IFERROR(VLOOKUP($B$4&"::1",Data_RepoDimensionRollups!$A:$F,6,FALSE),"") | F22: Hotspot 2 | G22: =IFERROR(IF(VLOOKUP($B$4,Data_RepoDetail!$A:$BZ,25,FALSE)="","No hotspot recorded yet.",VLOOKUP($B$4,Data_RepoDetail!$A:$BZ,25,FALSE)),"No hotspot recorded yet.")
A23: 2 | B23: =IFERROR(VLOOKUP($B$4&"::2",Data_RepoDimensionRollups!$A:$F,4,FALSE),"") | C23: =IFERROR(VLOOKUP($B$4&"::2",Data_RepoDimensionRollups!$A:$F,5,FALSE),"") | D23: =IFERROR(VLOOKUP($B$4&"::2",Data_RepoDimensionRollups!$A:$F,6,FALSE),"") | F23: Hotspot 3 | G23: =IFERROR(IF(VLOOKUP($B$4,Data_RepoDetail!$A:$BZ,26,FALSE)="","No hotspot recorded yet.",VLOOKUP($B$4,Data_RepoDetail!$A:$BZ,26,FALSE)),"No hotspot recorded yet.")
A24: 3 | B24: =IFERROR(VLOOKUP($B$4&"::3",Data_RepoDimensionRollups!$A:$F,4,FALSE),"") | C24: =IFERROR(VLOOKUP($B$4&"::3",Data_RepoDimensionRollups!$A:$F,5,FALSE),"") | D24: =IFERROR(VLOOKUP($B$4&"::3",Data_RepoDimensionRollups!$A:$F,6,FALSE),"")
A25: 4 | B25: =IFERROR(VLOOKUP($B$4&"::4",Data_RepoDimensionRollups!$A:$F,4,FALSE),"") | C25: =IFERROR(VLOOKUP($B$4&"::4",Data_RepoDimensionRollups!$A:$F,5,FALSE),"") | D25: =IFERROR(VLOOKUP($B$4&"::4",Data_RepoDimensionRollups!$A:$F,6,FALSE),"") | F25: What To Do Next
A26: 5 | B26: =IFERROR(VLOOKUP($B$4&"::5",Data_RepoDimensionRollups!$A:$F,4,FALSE),"") | C26: =IFERROR(VLOOKUP($B$4&"::5",Data_RepoDimensionRollups!$A:$F,5,FALSE),"") | D26: =IFERROR(VLOOKUP($B$4&"::5",Data_RepoDimensionRollups!$A:$F,6,FALSE),"") | F26: Recommended Action | G26: =IFERROR(IF(VLOOKUP($B$4,Data_RepoDetail!$A:$BZ,22,FALSE)="","No clear next action is recorded yet.",VLOOKUP($B$4,Data_RepoDetail!$A:$BZ,22,FALSE)),"No clear next action is recorded yet.")
A27: 6 | B27: =IFERROR(VLOOKUP($B$4&"::6",Data_RepoDimensionRollups!$A:$F,4,FALSE),"") | C27: =IFERROR(VLOOKUP($B$4&"::6",Data_RepoDimensionRollups!$A:$F,5,FALSE),"") | D27: =IFERROR(VLOOKUP($B$4&"::6",Data_RepoDimensionRollups!$A:$F,6,FALSE),"") | F27: Why This Action | G27: =IFERROR(IF(VLOOKUP($B$4,Data_RepoDetail!$A:$BZ,23,FALSE)="","No action rationale is recorded yet.",VLOOKUP($B$4,Data_RepoDetail!$A:$BZ,23,FALSE)),"No action rationale is recorded yet.")
A28: Where To Start | F28: Follow-Through Status | G28: =IFERROR(IF(VLOOKUP($B$4,Data_RepoDetail!$A:$BZ,32,FALSE)="","Unknown",VLOOKUP($B$4,Data_RepoDetail!$A:$BZ,32,FALSE)),"Unknown")
A29: Summary | B29: =IFERROR(IF(VLOOKUP($B$4,Data_RepoDetail!$A:$BZ,66,FALSE)="","No meaningful implementation hotspot is currently surfaced.",VLOOKUP($B$4,Data_RepoDetail!$A:$BZ,66,FALSE)),"No meaningful implementation hotspot is currently surfaced.") | F29: Follow-Through Summary | G29: =IFERROR(IF(VLOOKUP($B$4,Data_RepoDetail!$A:$BZ,33,FALSE)="","No follow-through evidence is recorded yet.",VLOOKUP($B$4,Data_RepoDetail!$A:$BZ,33,FALSE)),"No follow-through evidence is recorded yet.")
A30: Implementation Hotspot 1 | B30: =IFERROR(IF(VLOOKUP($B$4,Data_RepoDetail!$A:$BZ,67,FALSE)="","No implementation hotspot is currently surfaced.",VLOOKUP($B$4,Data_RepoDetail!$A:$BZ,67,FALSE)),"No implementation hotspot is currently surfaced.") | F30: Checkpoint Timing | G30: =IFERROR(IF(VLOOKUP($B$4,Data_RepoDetail!$A:$BZ,34,FALSE)="","Unknown",VLOOKUP($B$4,Data_RepoDetail!$A:$BZ,34,FALSE)),"Unknown")
A31: Implementation Hotspot 2 | B31: =IFERROR(IF(VLOOKUP($B$4,Data_RepoDetail!$A:$BZ,68,FALSE)="","No second implementation hotspot is currently surfaced.",VLOOKUP($B$4,Data_RepoDetail!$A:$BZ,68,FALSE)),"No second implementation hotspot is currently surfaced.") | F31: Escalation | G31: =IFERROR(IF(VLOOKUP($B$4,Data_RepoDetail!$A:$BZ,35,FALSE)="","Unknown",VLOOKUP($B$4,Data_RepoDetail!$A:$BZ,35,FALSE)),"Unknown")
A32: Implementation Hotspot 3 | B32: =IFERROR(IF(VLOOKUP($B$4,Data_RepoDetail!$A:$BZ,69,FALSE)="","No third implementation hotspot is currently surfaced.",VLOOKUP($B$4,Data_RepoDetail!$A:$BZ,69,FALSE)),"No third implementation hotspot is currently surfaced.") | F32: Escalation Summary | G32: =IFERROR(IF(VLOOKUP($B$4,Data_RepoDetail!$A:$BZ,36,FALSE)="","No stronger follow-through escalation is currently surfaced.",VLOOKUP($B$4,Data_RepoDetail!$A:$BZ,36,FALSE)),"No stronger follow-through escalation is currently surfaced.")
F33: Recovery / Retirement | G33: =IFERROR(IF(VLOOKUP($B$4,Data_RepoDetail!$A:$BZ,37,FALSE)="","None",VLOOKUP($B$4,Data_RepoDetail!$A:$BZ,37,FALSE)),"None")
A34: Arc F Signals | F34: Recovery Summary | G34: =IFERROR(IF(VLOOKUP($B$4,Data_RepoDetail!$A:$BZ,38,FALSE)="","No follow-through recovery or escalation-retirement signal is currently surfaced.",VLOOKUP($B$4,Data_RepoDetail!$A:$BZ,38,FALSE)),"No follow-through recovery or escalation-retirement signal is currently surfaced.")
A35: README Stale | B35: =IFERROR(VLOOKUP($B$4,Data_RepoDetail!$A:$BZ,71,FALSE),"—") | F35: Recovery Persistence | G35: =IFERROR(IF(VLOOKUP($B$4,Data_RepoDetail!$A:$BZ,39,FALSE)="","None",VLOOKUP($B$4,Data_RepoDetail!$A:$BZ,39,FALSE)),"None")
A36: Staleness Ratio | B36: =IFERROR(VLOOKUP($B$4,Data_RepoDetail!$A:$BZ,72,FALSE),"—") | F36: Recovery Persistence Summary | G36: =IFERROR(IF(VLOOKUP($B$4,Data_RepoDetail!$A:$BZ,40,FALSE)="","No follow-through recovery persistence signal is currently surfaced.",VLOOKUP($B$4,Data_RepoDetail!$A:$BZ,40,FALSE)),"No follow-through recovery persistence signal is currently surfaced.")
A37: README Last Touched (days) | B37: =IFERROR(VLOOKUP($B$4,Data_RepoDetail!$A:$BZ,73,FALSE),"—") | F37: Relapse Churn | G37: =IFERROR(IF(VLOOKUP($B$4,Data_RepoDetail!$A:$BZ,41,FALSE)="","None",VLOOKUP($B$4,Data_RepoDetail!$A:$BZ,41,FALSE)),"None")
A38: Code Last Touched (days) | B38: =IFERROR(VLOOKUP($B$4,Data_RepoDetail!$A:$BZ,74,FALSE),"—") | F38: Relapse Churn Summary | G38: =IFERROR(IF(VLOOKUP($B$4,Data_RepoDetail!$A:$BZ,42,FALSE)="","No relapse churn is currently surfaced.",VLOOKUP($B$4,Data_RepoDetail!$A:$BZ,42,FALSE)),"No relapse churn is currently surfaced.")
A39: Has Any Release | B39: =IFERROR(VLOOKUP($B$4,Data_RepoDetail!$A:$BZ,75,FALSE),"No") | F39: Recovery Freshness | G39: =IFERROR(IF(VLOOKUP($B$4,Data_RepoDetail!$A:$BZ,43,FALSE)="","None",VLOOKUP($B$4,Data_RepoDetail!$A:$BZ,43,FALSE)),"None")
A40: Latest Release Age (days) | B40: =IFERROR(VLOOKUP($B$4,Data_RepoDetail!$A:$BZ,76,FALSE),"—") | F40: Recovery Freshness Summary | G40: =IFERROR(IF(VLOOKUP($B$4,Data_RepoDetail!$A:$BZ,44,FALSE)="","No follow-through recovery freshness signal is currently surfaced.",VLOOKUP($B$4,Data_RepoDetail!$A:$BZ,44,FALSE)),"No follow-through recovery freshness signal is currently surfaced.")
A41: OSSF Score | B41: =IFERROR(VLOOKUP($B$4,Data_RepoDetail!$A:$BZ,77,FALSE),"—") | F41: Recovery Memory Reset | G41: =IFERROR(IF(VLOOKUP($B$4,Data_RepoDetail!$A:$BZ,45,FALSE)="","None",VLOOKUP($B$4,Data_RepoDetail!$A:$BZ,45,FALSE)),"None")
A42: OSSF Top Failing Checks | B42: =IFERROR(VLOOKUP($B$4,Data_RepoDetail!$A:$BZ,78,FALSE),"—") | F42: Recovery Memory Reset Summary | G42: =IFERROR(IF(VLOOKUP($B$4,Data_RepoDetail!$A:$BZ,46,FALSE)="","No follow-through recovery memory reset signal is currently surfaced.",VLOOKUP($B$4,Data_RepoDetail!$A:$BZ,46,FALSE)),"No follow-through recovery memory reset signal is currently surfaced.")
...

Sheet Executive Summary
A1: Executive Summary | N1: Quick Links
A2: Profile: default | Collection: all | N2: Dashboard
A3: Use the left side for the short leadership story and the right side for operator evidence you may need to defend the next move. | N3: Review Queue
A4: Leadership Brief | N4: Repo Detail
A5: Portfolio Health | B5: 1 repos are shipped, the portfolio average is 0.65, and RepoA set the current high-water mark. | N5: Run Changes
A6: Top Attention | B6: RepoC still needs security follow-through before the queue will calm down. Critical security pressure is concentrated in 1 repos. | N6: Executive Summary
A7: Run Changes | B7: Average score moved +0.020; 0 meaningful improvements, 0 regressions, 1 promotions, and 1 demotions were recorded.
A8: Queue Pressure | B8: 1 blocked, 1 urgent, 1 ready, and 1 deferred item(s) are currently in the queue.
A9: What Changed | B9: RepoC drift needs review and RepoB reopened a release checklist item.
A10: Portfolio Grade | C10: Avg Score | E10: Critical Repos | G10: Improving | I10: Regressing
A11: B | C11: 0.65 | E11: 1 | G11: 0 | I11: 0
A12: Follow-Through Hotspot | B12: No outstanding follow-through hotspot
A13: Escalation Hotspot | B13: No outstanding follow-through hotspot
A14: Top Profile Leaders | B14: No active recovery or retirement hotspot | E14: Top Movers | I14: Top 5 Attention Items
A15: Repo | B15: Profile Score | C15: Tier | E15: Repo | F15: Delta | G15: Tier Change | I15: Repo | J15: Counts | K15: Why Now | L15: Next Step
A16: RepoA | B16: 0.88 | C16: shipped | E16: RepoA | F16: 0.09 | G16: functional -> shipped | I16: RepoC | J16: B1/U0/R0 | K16: Security drift needs review | L16: Open the governed control preview and decide whether to apply CodeQL.
A17: RepoB | B17: 0.62 | C17: functional | E17: RepoC | F17: -0.08 | G17: functional -> wip | I17: RepoB | J17: B0/U1/R0 | K17: Release checklist reopened | L17: Re-run the release checklist and close the missing item.
A18: RepoC | B18: 0.44 | C18: wip | I18: RepoA | J18: B0/U0/R1 | K18: Archive old brainstorm notes | L18: Leave this alone unless priorities change.
A19: Rebuild Hotspot | B19: No rebuilding recovery-memory hotspot
A20: Rebuild Strength Hotspot | B20: No rebuilding-after-reset hotspot
A21: Reacquiring Hotspot | B21: No near-reacquisition hotspot
A22: Scenario Preview | B22: No re-acquired hotspot | D22: Operator Control Center
A23: Projected Avg Score Delta | B23: 0 | D23: Headline | E23: RepoC still needs security follow-through before the queue will calm down.
A24: Projected Promotions | B24: 0 | D24: Queue Counts | E24: 1 blocked, 1 urgent, 1 ready, 1 deferred
A25: Holding Reacquired Hotspot | B25: No holding re-acquisition hotspot | D25: Source Run | E25: sample-user:2026-04-12T12:00:00+00:00
A26: Durable Reacquired Hotspot | B26: No durable re-acquisition hotspot | D26: Next Run | E26: incremental via adaptive
A27: Softening Reacquired Hotspot | B27: No softening re-acquisition hotspot | D27: Watch Decision | E27: The current baseline is still compatible, so incremental watch remains safe for the next run.
A28: Fragile Reacquisition Confidence Hotspot | B28: No fragile re-acquisition confidence hotspot | D28: What To Do Next | E28: Review RepoC first, then close RepoB's reopened checklist item.
A29: Reacquisition Softening Hotspot | B29: No reacquisition softening hotspot | D29: Trend | E29: Stable — Queue pressure is stable but still sticky.
A30: Revalidation Needed Hotspot | B30: No reacquisition revalidation hotspot | D30: Primary Target | E30: No active target
A31: Retired Confidence Hotspot | B31: No retired re-acquisition confidence hotspot | D31: Resolution Counts | E31: New 0 | Resolved 0 | Persisting 0
A32: Under Revalidation Hotspot | B32: No under-revalidation recovery hotspot | D32: Why Top Target | E32: RepoC remains the top target because live drift is still open.
A33: Rebuilding Restored Confidence Hotspot | B33: No rebuilding restored-confidence hotspot | D33: Closure Guidance | E33: Clear RepoC's security drift before moving to lower-pressure work.
A34: Re-Earning Confidence Hotspot | B34: No confidence re-earning hotspot | D34: Aging Pressure | E34: Chronic 0 | Newly stale 0 | Longest No persisting item
A35: Just Re-Earned Confidence Hotspot | B35: No just re-earned confidence hotspot | D35: What We Tried | E35: No recent intervention recorded
A36: Holding Re-Earned Confidence Hotspot | B36: No holding re-earned confidence hotspot | D36: Last Outcome | E36: No Change
... A88: Reacquisition Durability | B88: No follow-through reacquisition durability signal is currently surfaced. | D88: Calibration Snapshot | E88: High-confidence hit rate 0% | 0 reopened
A89: Reacquisition Confidence | B89: No follow-through reacquisition confidence-consolidation signal is currently surfaced.
A90: Operator Focus | B90: Act Now
A91: Focus Summary | B91: 2 item(s) need immediate action first, led by RepoC, RepoB.
...

Sheet By Lens
A1: By Lens | K1: Quick Links
A2: Compare the same repos through different decision lenses so you can separate shipped work, risk, momentum, and showcase value. | K2: Dashboard
A3: Current view: profile default | collection all | use this sheet to compare the same repo through multiple decision lenses. | K3: Review Queue
K4: Repo Detail
A5: Repo | B5: Profile Score | C5: Tier | D5: Ship Readiness | E5: Maintenance Risk | F5: Showcase | G5: Security | H5: Momentum | I5: Portfolio Fit | K5: Run Changes
A6: RepoA | B6: 0.88 | C6: shipped | D6: 0.89 | E6: 0 | F6: 0 | G6: 0.82 | H6: 0.75 | I6: 0.86 | K6: Executive Summary
A7: RepoB | B7: 0.62 | C7: functional | D7: 0.63 | E7: 0 | F7: 0 | G7: 0.66 | H7: 0.54 | I7: 0.58
A8: RepoC | B8: 0.44 | C8: wip | D8: 0.42 | E8: 0 | F8: 0 | G8: 0.28 | H8: 0.31 | I8: 0.36

Sheet By Collection
A1: By Collection | J1: Quick Links
A2: Use this sheet to understand which collections are concentrated, which repos lead them, and where your showcase value is clustered. | J2: Dashboard
A3: Current profile: default. Use this sheet to see how each collection groups related repos and where its best work sits. | J3: Review Queue
J4: Repo Detail
A5: Collection | B5: Repos | C5: Description | D5: Top Repo | E5: Top Score | J5: Run Changes
A6: showcase | B6: 1 | C6: Best examples to show other people. | D6: RepoA | E6: 0.88 | J6: Executive Summary

Sheet Trend Summary
A1: Trend Summary | J1: Quick Links
A2: Track portfolio movement over time, then scan the short repo trendlines below to see who is actually improving or drifting. | J2: Dashboard
A3: Use this sheet when you want portfolio-wide movement first, then repo-level trendlines second. | J3: Review Queue
J4: Repo Detail
A5: Date | B5: Average Score | C5: Repos | D5: Shipped | E5: Functional | F5: Review Emitted | G5: Campaign Drift | H5: Governance Drift | J5: Run Changes
A6: 2026-04-12 | B6: 0.65 | C6: 3 | D6: 1 | E6: 1 | F6: yes | G6: 1 | H6: 1 | J6: Executive Summary
A9: Top Repo Trendlines
A10: Repo | B10: Trendline | C10: Latest Score
A11: RepoA | C11: 0.88
A12: RepoB | C12: 0.62
A13: RepoC | C13: 0.44

Sheet Run Changes
A1: Run Changes | N1: Quick Links
A2: Use this sheet to answer one question quickly: what moved since the last run, and what actually needs follow-through now? | N2: Dashboard
A3: Average score moved +0.020; 0 meaningful improvements, 0 regressions, 1 promotions, and 1 demotions were recorded. | N3: Review Queue
A4: Read this page top to bottom: scan the summary cards first, then check regressions, blocked items, and new security or governance pressure. | N4: Repo Detail
A5: Comparison Window | B5: 2026-04-05 -> 2026-04-12 | N5: Run Changes
A6: Improvements | C6: Regressions | E6: Promotions | G6: Demotions | I6: Security | K6: Governance | N6: Executive Summary
A7: 0 | C7: 0 | E7: 1 | G7: 1 | I7: 1 | K7: 1
A9: Biggest Score Gains
A10: Repo | B10: Delta | C10: New Score
A11: RepoA | B11: 0.09 | C11: 0.88
A12: RepoB | B12: -0.06 | C12: 0.62
A13: RepoC | B13: -0.08 | C13: 0.44
A15: Biggest Regressions
A16: Repo | B16: Delta | C16: New Score
A17: RepoC | B17: -0.08 | C17: 0.44
A18: RepoB | B18: -0.06 | C18: 0.62
A19: RepoA | B19: 0.09 | C19: 0.88
A21: Tier Promotions / Demotions
A22: Repo | B22: Old Tier | C22: New Tier | D22: Movement
A23: RepoA | B23: functional | C23: shipped | D23: promotion
A24: RepoC | B24: functional | C24: wip | D24: demotion
A26: Newly Blocked Items
A27: Repo | B27: Item | C27: Why
A28: RepoC | B28: Security drift needs review | C28: Governed security drift is still unresolved.
A30: Reopened Items
A31: Repo | B31: Title | C31: Type
A32: RepoB | B32: Release checklist reopened | C32: reopened-review
A34: New Security / Governance Pressure
A35: Repo | B35: Signal | C35: Area
A36: sample-user/RepoC | B36: already-enabled | C36: governance
A37: RepoC | B37: critical | C37: security

Sheet Campaigns
A1: Campaigns | M1: Quick Links
A2: Managed campaign state stays local-authoritative here. This sheet is where you see open work, stale items, and whether there is anything to reconcile. | M2: Dashboard
M3: Review Queue
A4: Current Campaign State | J4: Action Sync Readiness | M4: Repo Detail
A5: Campaign | B5: Security Review | J5: Action Sync Readiness | K5: No current campaign needs Action Sync yet, so the safest next move is to keep the story local. | M5: Run Changes
A6: Request State | B6: Campaign requested from the current report facts. | J6: Next Action Sync Step | K6: Stay local for now; no current campaign needs preview or apply. | M6: Executive Summary
A7: Row State | B7: Campaign rows are present. External mutation stays manual until writeback apply is explicitly requested. | J7: Apply Packet | K7: No current campaign has a safe execution handoff yet, so the local story should stay local for now.
A8: Profile | B8: default | J8: Command Hint | K8: No Action Sync command is recommended yet.
A9: Collection | B9: all | J9: Post-Apply Monitoring | K9: No recent Action Sync apply needs post-apply monitoring yet, so the local weekly story can stay local.
A10: Actions | B10: 1 | J10: Next Monitoring Step | K10: Stay local for now; no recent Action Sync apply needs post-apply follow-up yet.
A11: Repos | B11: 1 | J11: Campaign Tuning | K11: Campaign tuning is neutral because there is not enough outcome history yet to bias tied recommendations.
A12: Sync Mode | B12: reconcile | J12: Next Tie-Break Candidate | K12: No current campaign needs a tuning tie-break yet.
A13: GitHub Projects | B13: disabled | J13: Historical Portfolio Intelligence | K13: Historical portfolio intelligence is still thin, so the weekly story should stay grounded in the current run and recent operator queue.
J14: Next Historical Focus | K14: Stay local for now; no repo has enough cross-run intervention evidence to demand a historical follow-up read yet.
A15: Repo | B15: Issue | C15: Topics | D15: Projects | E15: Notion Actions | F15: Action IDs | G15: Drift | H15: Sync Mode | J15: Automation Guidance | K15: Automation guidance stays quiet until a campaign has a clearly safe preview, follow-up, or manual-only posture.
A16: RepoC | B16: [Repo Auditor] Security Review | C16: ghra-call-security-review | D16: 0 | E16: 1 | G16: no | H16: reconcile | J16: Next Safe Automation Step | K16: Stay local for now; no current campaign has a stronger safe automation posture than manual review.
J17: Approval Workflow | K17: No current approval needs review yet, so the approval workflow can stay local for now.
J18: Next Approval Review | K18: Stay local for now; no current approval needs review.

Sheet Governance Controls
A1: Governance Controls | J1: Quick Links
A2: This sheet shows the current governed control family only: readiness, drift, re-approval need, and rollback visibility. | J2: Dashboard
J3: Review Queue
A4: Governance Snapshot | J4: Repo Detail
A5: Status | B5: Drifted | J5: Run Changes
A6: Selected View | B6: all | J6: Executive Summary
A7: Approval | B7: Preview only
A8: Needs Re-Approval | B8: no
A9: Rollback Available | B9: 1
A10: Headline | B10: Governed security drift needs review.
A11: Repo | B11: Action | C11: State | D11: Expected Lift | E11: Effort | F11: Source | G11: Why
A12: RepoC | B12: Enable CodeQL default setup | C12: Ready | D12: 0.12 | F12: github

Sheet Print Pack
A1: Print Pack | J1: Quick Links
A2: Profile: default | Collection: all | J2: Dashboard
J3: Review Queue
A4: Page 1: Leadership Brief | D4: Workflow Guidance | J4: Repo Detail
A5: Portfolio Grade | B5: B | D5: Product Mode | E5: Action Sync: use this artifact to confirm the local campaign story first, then preview or apply GitHub, GitHub Projects, or Notion mirrors only after the repo-level decision is settled. | J5: Run Changes
A6: Average Score | B6: 0.65 | D6: Artifact Role | E6: Local report remains authoritative; campaigns, writeback, and GitHub Projects are managed mirrors of the decision already made here. | J6: Executive Summary
A7: Portfolio Headline | B7: RepoC still needs security follow-through before the queue will calm down. | D7: Reading Order | E7: Read Review Queue first, then the control-center headline and primary target, then the campaign preview or writeback section before syncing outward.
A8: Queue Pressure | B8: 1 blocked, 1 urgent, 1 ready, and 1 deferred item(s) are currently in the queue. | D8: Next Best Step | E8: Keep the local artifact as the source of truth, then use campaign preview or writeback only when the repo decision is already clear.
A9: Run Changes | B9: Average score moved +0.020; 0 meaningful improvements, 0 regressions, 1 promotions, and 1 demotions were recorded. | D9: Action Sync Readiness | E9: No current campaign needs Action Sync yet, so the safest next move is to keep the story local.
A10: What To Do This Week | B10: Review RepoC first, then close RepoB's reopened checklist item. Start with RepoC if you need a concrete place to begin. | D10: Next Action Sync Step | E10: Stay local for now; no current campaign needs preview or apply.
A11: Trust / Actionability | B11: verify-first — The recommendation is sound, but recent reopen noise means it should still be reviewed before acting. | D11: Apply Packet | E11: No current campaign has a safe execution handoff yet, so the local story should stay local for now.
A12: Top Attention Items | B12: 4 | D12: Command Hint | E12: No Action Sync command is recommended yet.
A13: What Changed | B13: RepoC drift needs review and RepoB reopened a release checklist item. | D13: Post-Apply Monitoring | E13: No recent Action Sync apply needs post-apply monitoring yet, so the local weekly story can stay local.
A14: Why It Matters | B14: Live drift is still present, so security work should stay ahead of lower-pressure cleanup. | D14: Next Monitoring Step | E14: Stay local for now; no recent Action Sync apply needs post-apply follow-up yet.
A15: Decision This Week | B15: Review RepoC first, then close RepoB's reopened checklist item. | D15: Campaign Tuning | E15: Campaign tuning stays neutral until there is enough outcome history to bias tied recommendations.
A16: Follow-Through | B16: Act Now: Governed security drift is still unresolved. Next checkpoint: Use the next run or linked artifact to confirm whether the recommendation moved. | D16: Next Tie-Break Candidate | E16: No current campaign needs a tie-break candidate yet.
A17: Primary Target | B17: No active target | D17: Historical Portfolio Intelligence | E17: Historical portfolio intelligence is still thin, so the weekly story should stay grounded in the current run and recent operator queue.
A18: Why Top Target | B18: RepoC remains the top target because live drift is still open. | D18: Next Historical Focus | E18: Stay local for now; no repo has enough cross-run intervention evidence to demand a historical follow-up read yet.
A19: Recovery / Retirement | B19: No follow-through recovery or escalation-retirement signal is currently surfaced. | D19: Automation Guidance | E19: Automation guidance stays quiet until a campaign has a clearly safe preview, follow-up, or manual-only posture.
A20: Recovery Persistence | B20: No follow-through recovery persistence signal is currently surfaced. | D20: Next Safe Automation Step | E20: Stay local for now; no current campaign has a stronger safe automation posture than manual review.
A21: Relapse Churn | B21: No relapse churn is currently surfaced. | D21: Approval Workflow | E21: No current approval needs review yet, so the approval workflow can stay local for now.
A22: Recovery Freshness | B22: No follow-through recovery freshness signal is currently surfaced. | D22: Next Approval Review | E22: Stay local for now; no current approval needs review.
A23: Recovery Memory Reset | B23: No follow-through recovery memory reset signal is currently surfaced.
A24: Recovery Rebuild Strength | B24: No follow-through recovery rebuild-strength signal is currently surfaced.
A25: Recovery Reacquisition | B25: No follow-through recovery reacquisition signal is currently surfaced.
A26: Reacquisition Durability | B26: No follow-through reacquisition durability signal is currently surfaced.
A27: Reacquisition Confidence | B27: No follow-through reacquisition confidence-consolidation signal is currently surfaced.
A28: Operator Focus | B28: Act Now
A29: Focus Summary | B29: 2 item(s) need immediate action first, led by RepoC, RepoB.
A30: Focus Line | B30: Act Now: Governed security drift is still unresolved.
A31: What We Tried | B31: No recent intervention recorded
A32: Last Outcome | B32: No Change
A33: Resolution Evidence | B33: No resolution evidence is recorded yet.
A34: Recovery Counts | B34: Confirmed resolved 0 | Reopened 0
... A69: Calibration Snapshot | B69: High-confidence hit rate 0% | 0 reopened
A70: Top Attention | E70: Top Repo Drilldowns
A71: RepoC | B71: Act Now | C71: Governed security drift is still unresolved. | D71: Open the governed control preview and decide whether to apply CodeQL. | E71: RepoC | F71: Open the governed control preview and decide whether to apply CodeQL. No action rationale is recorded yet.
A72: RepoB | B72: Act Now | C72: A previously quiet repo reopened a visible checklist item. | D72: Re-run the release checklist and close the missing item. | E72: RepoB | F72: Re-run the release checklist and close the missing item. No action rationale is recorded yet.
A73: RepoA | B73: Watch Closely | C73: RepoA is healthy enough that a small polish task would keep it strong. | D73: Tidy the release notes and publish the next small maintenance release. | E73: RepoA | F73: Tidy the release notes and publish the next small maintenance release. No action rationale is recorded yet.
A74: RepoA | B74: Watch Closely | C74: This is cleanup-only work with no current pressure. | D74: Leave this alone unless priorities change.
...

Sheet Action Items
A1: Action Items — 4 prioritized improvements
A7: All Actions (Prioritized)
A8: # | B8: Repo | C8: Action | D8: Impact | E8: Effort | F8: Dimension
A9: 1 | B9: RepoC | C9: Improve testing (currently 0.2) | D9: Close 0.110 gap to functional | E9: Med | F9: testing
A10: 2 | B10: RepoC | C10: Improve security (currently 0.2) | D10: Close 0.110 gap to functional | E10: Med | F10: security
A11: 3 | B11: RepoB | C11: Improve release (currently 0.5) | D11: Close 0.130 gap to shipped | E11: Med | F11: release
A12: 4 | B12: RepoB | C12: Improve testing (currently 0.6) | D12: Close 0.130 gap to shipped | E12: Med | F12: testing

Sheet Activity
A1: Repo | B1: Commit Pattern | C1: Days Since Push | D1: Total Commits | E1: Recent 3mo | F1: Bus Factor | G1: Release Count | H1: Activity Score | I1: Tier
A2: RepoA | B2: — | C2: — | D2: — | E2: — | F2: — | G2: — | H2: 0 | I2: shipped
A3: RepoB | B3: — | C3: — | D3: — | E3: — | F3: — | G3: — | H3: 0 | I3: functional
A4: RepoC | B4: — | C4: — | D4: — | E4: — | F4: — | G4: — | H4: 0 | I4: wip

Sheet All Repos
A1: Repo | B1: Grade | C1: Score | D1: Interest | E1: Interest Grade | F1: Interest Tier | G1: Tier | H1: Badges | I1: Next Badge | J1: Language | K1: Topics | L1: Commit Pattern | M1: Bus Factor | N1: Days Since Push | O1: Commits | P1: Releases | Q1: Has Release | R1: README Stale | S1: Test Files | T1: Test Framework | U1: LOC | V1: TODO Density | W1: PR Merge % | X1: Comment Ratio | Y1: Dep Count | Z1: Libyears | AA1: Stars | AB1: Private | AC1: Flags | AD1: Description | AE1: Biggest Drag | AF1: Why This Grade | AG1: Tech Novelty | AH1: Burst | AI1: Ambition | AJ1: Storytelling | AK1: Created | AL1: Size (KB) | AM1: Trend | AN1: Risk Tier | AP1: Quick Links
A2: RepoA | B2: A | C2: 0.88 | D2: 0.61 | E2: — | F2: — | G2: shipped | H2: fresh, tested | J2: Python | K2: python, cli | L2: — | M2: — | N2: — | O2: — | P2: — | Q2: No | R2: No | S2: 0 | T2: — | U2: 0 | V2: 0 | W2: 0 | X2: 0 | Y2: — | Z2: — | AA2: 12 | AB2: No | AD2: A polished shipped project. | AE2: documentation (0.8) | AF2: A: documentation=0.8, testing=0.9 | AG2: 0 | AH2: 0 | AI2: 0 | AJ2: 0 | AL2: 0 | AP2: Dashboard
A3: RepoB | B3: C | C3: 0.62 | D3: 0.37 | E3: — | F3: — | G3: functional | J3: TypeScript | K3: typescript, web | L3: — | M3: — | N3: — | O3: — | P3: — | Q3: No | R3: No | S3: 0 | T3: — | U3: 0 | V3: 0 | W3: 0 | X3: 0 | Y3: — | Z3: — | AA3: 5 | AB3: No | AC3: release-checklist-open | AD3: A functional project with follow-through left to do. | AE3: release (0.5) | AF3: C: release=0.5, testing=0.6 | AG3: 0 | AH3: 0 | AI3: 0 | AJ3: 0 | AL3: 0 | AP3: Review Queue
A4: RepoC | B4: D | C4: 0.44 | D4: 0.16 | E4: — | F4: — | G4: wip | J4: Python | K4: python, security | L4: — | M4: — | N4: — | O4: — | P4: — | Q4: No | R4: No | S4: 0 | T4: — | U4: 0 | V4: 0 | W4: 0 | X4: 0 | Y4: — | Z4: — | AA4: 1 | AB4: No | AC4: no-tests, security-review | AD4: A risky work-in-progress project. | AE4: testing (0.2) | AF4: D: testing=0.2, security=0.2 | AG4: 0 | AH4: 0 | AI4: 0 | AJ4: 0 | AL4: 0 | AP4: Repo Detail
A5: SUMMARY | C5: =AVERAGE(C2:C4) | D5: =AVERAGE(D2:D4) | AP5: Run Changes
AP6: Executive Summary

Sheet Badges
A1: Badge Dashboard
A2: Total badges earned: 2 across 3 repos
A4: Badge | B4: Repos Earned | C4: % of Portfolio
A5: fresh | B5: 1 | C5: 33%
A6: tested | B6: 1 | C6: 33%
A9: Achievement Board
A10: Repo | B10: Badges
A11: RepoA | B11: 2
A12: RepoB | B12: 0
A13: RepoC | B13: 0

Sheet Changes
A1: Changes Since Last Audit
